<?xml version="1.0" ?>
<sdf version="1.7">
  <model name="simple_agv">
    <pose>2.5 0 0.1 0 0 0</pose> <!-- Initial position on the ground -->

    <!-- Chassis -->
    <link name="chassis">
      <pose>0 0 0.1 0 0 0</pose>
      <inertial>
        <mass>10.0</mass>
        <inertia>
          <ixx>0.5</ixx>
          <iyy>0.5</iyy>
          <izz>0.5</izz>
        </inertia>
      </inertial>
      <collision name="collision">
        <geometry>
          <box>
            <size>0.6 0.4 0.2</size>
          </box>
        </geometry>
        <surface>
          <friction>
            <ode>
              <mu>1.5</mu>
              <mu2>1.5</mu2>
            </ode>
          </friction>
        </surface>
      </collision>
      <visual name="visual">
        <geometry>
          <box>
            <size>0.6 0.4 0.2</size>
          </box>
        </geometry>
        <material>
          <ambient>0.1 0.5 0.8 1</ambient>
        </material>
      </visual>
    </link>

    <!-- Wheels -->

    <!-- Front Left -->
    <link name="wheel_fl">
      <pose>0.2 0.2 0.025 0 0 0</pose>
      <collision name="collision">
        <geometry>
          <cylinder>
            <radius>0.05</radius>
            <length>0.03</length>
          </cylinder>
        </geometry>
        <pose>0 0 0 1.5708 0 0</pose> <!-- Rotate to spin around Y-axis -->
        <surface>
          <friction>
            <ode>
              <mu>2.0</mu>
              <mu2>2.0</mu2>
            </ode>
          </friction>
        </surface>
      </collision>
      <visual name="visual">
        <geometry>
          <cylinder>
            <radius>0.05</radius>
            <length>0.03</length>
          </cylinder>
        </geometry>
        <pose>0 0 0 1.5708 0 0</pose>
      </visual>
    </link>

    <!-- Front Right -->
    <link name="wheel_fr">
      <pose>0.2 -0.2 0.025 0 0 0</pose>
      <collision name="collision">
        <geometry>
          <cylinder>
            <radius>0.05</radius>
            <length>0.03</length>
          </cylinder>
        </geometry>
        <pose>0 0 0 1.5708 0 0</pose>
        <surface>
          <friction>
            <ode>
              <mu>2.0</mu>
              <mu2>2.0</mu2>
            </ode>
          </friction>
        </surface>
      </collision>
      <visual name="visual">
        <geometry>
          <cylinder>
            <radius>0.05</radius>
            <length>0.03</length>
          </cylinder>
        </geometry>
        <pose>0 0 0 1.5708 0 0</pose>
      </visual>
    </link>

    <!-- Rear Left -->
    <link name="wheel_rl">
      <pose>-0.2 0.2 0.025 0 0 0</pose>
      <collision name="collision">
        <geometry>
          <cylinder>
            <radius>0.05</radius>
            <length>0.03</length>
          </cylinder>
        </geometry>
        <pose>0 0 0 1.5708 0 0</pose>
      </collision>
      <visual name="visual">
        <geometry>
          <cylinder>
            <radius>0.05</radius>
            <length>0.03</length>
          </cylinder>
        </geometry>
        <pose>0 0 0 1.5708 0 0</pose>
      </visual>
    </link>

    <!-- Rear Right -->
    <link name="wheel_rr">
      <pose>-0.2 -0.2 0.025 0 0 0</pose>
      <collision name="collision">
        <geometry>
          <cylinder>
            <radius>0.05</radius>
            <length>0.03</length>
          </cylinder>
        </geometry>
        <pose>0 0 0 1.5708 0 0</pose>
      </collision>
      <visual name="visual">
        <geometry>
          <cylinder>
            <radius>0.05</radius>
            <length>0.03</length>
          </cylinder>
        </geometry>
        <pose>0 0 0 1.5708 0 0</pose>
      </visual>
    </link>

    <!-- Wheel Joints -->
    <joint name="wheel_fl_joint" type="revolute">
      <parent>chassis</parent>
      <child>wheel_fl</child>
      <axis>
        <xyz>0 1 0</xyz>
        <limit>
          <lower>-1000</lower>
          <upper>1000</upper>
          <effort>1e6</effort>
          <velocity>100</velocity>
        </limit>
      </axis>
    </joint>

    <joint name="wheel_fr_joint" type="revolute">
      <parent>chassis</parent>
      <child>wheel_fr</child>
      <axis>
        <xyz>0 1 0</xyz>
        <limit>
          <lower>-1000</lower>
          <upper>1000</upper>
          <effort>1e6</effort>
          <velocity>100</velocity>
        </limit>
      </axis>
    </joint>

    <joint name="wheel_rl_joint" type="revolute">
      <parent>chassis</parent>
      <child>wheel_rl</child>
      <axis>
        <xyz>0 1 0</xyz>
        <limit>
          <lower>-1000</lower>
          <upper>1000</upper>
        </limit>
      </axis>
    </joint>

    <joint name="wheel_rr_joint" type="revolute">
      <parent>chassis</parent>
      <child>wheel_rr</child>
      <axis>
        <xyz>0 1 0</xyz>
        <limit>
          <lower>-1000</lower>
          <upper>1000</upper>
        </limit>
      </axis>
    </joint>

    <!-- Diff Drive Plugin (2WD) -->
    <plugin 
      name="ignition::gazebo::systems::DiffDrive"
      filename="libignition-gazebo-diff-drive-system.so">
      <left_joint>wheel_fl_joint</left_joint>
      <right_joint>wheel_fr_joint</right_joint>
      <wheel_separation>0.4</wheel_separation>
      <wheel_radius>0.05</wheel_radius>
      <odom_publish_tf>false</odom_publish_tf>
      <topic>/cmd_vel</topic>
      <odom_topic>/odom</odom_topic>
      <min_velocity>-1.0</min_velocity>
      <max_velocity>1.0</max_velocity>
      <min_acceleration>-1.0</min_acceleration>
      <max_acceleration>1.0</max_acceleration>
    </plugin>

  </model>
</sdf>
